Workbook
Name Срез_Груз: #N/A
Name Срез_Примечание: #N/A
Name Срез_Событие: #N/A

Sheet 1 Въезд на базу
A1: День нед | B1: Дата | C1: Время | D1: Событие | E1: Объект | F1: Груз | G1: Кол-во | H1: Примечание | I1: Name | J1: Folder Path | K1: RelativePath | L1: Подпись | M1: Ссылка на фото | N1: Камера
A2: пт | B2: 46171 | C2: 0.39275463 | D2: Въезд на базу | E2: Легковая темная | F2: доски | H2: на крыше | I2: GA3948333_4_20260529T092534Z.jpg | J2: C:\ВИДЕОНАБЛЮДЕНИЕ\1 Въезд на базу\ | K2: 1 Въезд на базу\GA3948333_4_20260529T092534Z.jpg | L2: пт 29.05.2026 — 09:25:34 | M2: =HYPERLINK(склад2въезд[[#This Row],[RelativePath]]) -> 1 Въезд на базу\GA3948333_4_20260529T092534Z.jpg | N2: =VLOOKUP(склад2въезд[[#This Row],[Name]], СпрСобытий!$F:$G, 2, FALSE) -> Въезд на базу
A3: сб | B3: 46172 | C3: 0.41222222 | D3: Въезд на базу | E3: Легковая серая | I3: GA3948333_4_20260530T095336Z.jpg | J3: C:\ВИДЕОНАБЛЮДЕНИЕ\1 Въезд на базу\ | K3: 1 Въезд на базу\GA3948333_4_20260530T095336Z.jpg | L3: сб 30.05.2026 — 09:53:36 | M3: =HYPERLINK(склад2въезд[[#This Row],[RelativePath]]) -> 1 Въезд на базу\GA3948333_4_20260530T095336Z.jpg | N3: =VLOOKUP(склад2въезд[[#This Row],[Name]], СпрСобытий!$F:$G, 2, FALSE) -> Въезд на базу
A4: сб | B4: 46172 | C4: 0.41385417 | D4: Выезд с территории | E4: Легковая серая | I4: GA3948333_4_20260530T095557Z.jpg | J4: C:\ВИДЕОНАБЛЮДЕНИЕ\1 Въезд на базу\ | K4: 1 Въезд на базу\GA3948333_4_20260530T095557Z.jpg | L4: сб 30.05.2026 — 09:55:57 | M4: =HYPERLINK(склад2въезд[[#This Row],[RelativePath]]) -> 1 Въезд на базу\GA3948333_4_20260530T095557Z.jpg | N4: =VLOOKUP(склад2въезд[[#This Row],[Name]], СпрСобытий!$F:$G, 2, FALSE) -> Въезд на базу
A5: вс | B5: 46173 | C5: 0.85645833 | D5: без событий | E5: Территория | I5: GA3948333_4_20260531T203318Z.jpg | J5: C:\ВИДЕОНАБЛЮДЕНИЕ\1 Въезд на базу\ | K5: 1 Въезд на базу\GA3948333_4_20260531T203318Z.jpg | L5: вс 31.05.2026 — 20:33:18 | M5: =HYPERLINK(склад2въезд[[#This Row],[RelativePath]]) -> 1 Въезд на базу\GA3948333_4_20260531T203318Z.jpg | N5: =VLOOKUP(склад2въезд[[#This Row],[Name]], СпрСобытий!$F:$G, 2, FALSE) -> Въезд на базу
A6: пн | B6: 46174 | C6: 0.29431713 | D6: Въезд на базу | E6: Рено логан серый, с прицепом | F6: порожний | I6: GA3948333_4_20260601T070349Z.jpg | J6: C:\ВИДЕОНАБЛЮДЕНИЕ\1 Въезд на базу\ | K6: 1 Въезд на базу\GA3948333_4_20260601T070349Z.jpg | L6: пн 01.06.2026 — 07:03:49 | M6: =HYPERLINK(склад2въезд[[#This Row],[RelativePath]]) -> 1 Въезд на базу\GA3948333_4_20260601T070349Z.jpg | N6: =VLOOKUP(склад2въезд[[#This Row],[Name]], СпрСобытий!$F:$G, 2, FALSE) -> Въезд на базу
A7: пн | B7: 46174 | C7: 0.54909722 | D7: Выезд с территории | E7: Газель белая, фургон | I7: GA3948333_4_20260601T131042Z.jpg | J7: C:\ВИДЕОНАБЛЮДЕНИЕ\1 Въезд на базу\ | K7: 1 Въезд на базу\GA3948333_4_20260601T131042Z.jpg | L7: пн 01.06.2026 — 13:10:42 | M7: =HYPERLINK(склад2въезд[[#This Row],[RelativePath]]) -> 1 Въезд на базу\GA3948333_4_20260601T131042Z.jpg | N7: =VLOOKUP(склад2въезд[[#This Row],[Name]], СпрСобытий!$F:$G, 2, FALSE) -> Въезд на базу
A8: пн | B8: 46174 | C8: 0.7666088 | D8: Въезд на базу | E8: Рено дастер серый, с прицепом | F8: порожний | I8: GA3948333_4_20260601T182355Z.jpg | J8: C:\ВИДЕОНАБЛЮДЕНИЕ\1 Въезд на базу\ | K8: 1 Въезд на базу\GA3948333_4_20260601T182355Z.jpg | L8: пн 01.06.2026 — 18:23:55 | M8: =HYPERLINK(склад2въезд[[#This Row],[RelativePath]]) -> 1 Въезд на базу\GA3948333_4_20260601T182355Z.jpg | N8: =VLOOKUP(склад2въезд[[#This Row],[Name]], СпрСобытий!$F:$G, 2, FALSE) -> Въезд на базу
A9: пн | B9: 46174 | C9: 0.82680556 | D9: Въезд на базу | E9: Камаз базы | F9: порожний | I9: GA3948333_4_20260601T195036Z.jpg | J9: C:\ВИДЕОНАБЛЮДЕНИЕ\1 Въезд на базу\ | K9: 1 Въезд на базу\GA3948333_4_20260601T195036Z.jpg | L9: пн 01.06.2026 — 19:50:36 | M9: =HYPERLINK(склад2въезд[[#This Row],[RelativePath]]) -> 1 Въезд на базу\GA3948333_4_20260601T195036Z.jpg | N9: =VLOOKUP(склад2въезд[[#This Row],[Name]], СпрСобытий!$F:$G, 2, FALSE) -> Въезд на базу
A10: пн | B10: 46174 | C10: 0.8283912 | D10: Выезд с территории | E10: Рено дастер серый | I10: GA3948333_4_20260601T195253Z.jpg | J10: C:\ВИДЕОНАБЛЮДЕНИЕ\1 Въезд на базу\ | K10: 1 Въезд на базу\GA3948333_4_20260601T195253Z.jpg | L10: пн 01.06.2026 — 19:52:53 | M10: =HYPERLINK(склад2въезд[[#This Row],[RelativePath]]) -> 1 Въезд на базу\GA3948333_4_20260601T195253Z.jpg | N10: =VLOOKUP(склад2въезд[[#This Row],[Name]], СпрСобытий!$F:$G, 2, FALSE) -> Въезд на базу
A11: пн | B11: 46174 | C11: 0.95895833 | D11: Въезд на базу | E11: Камаз базы | I11: GA3948333_4_20260601T230054Z.jpg | J11: C:\ВИДЕОНАБЛЮДЕНИЕ\1 Въезд на базу\ | K11: 1 Въезд на базу\GA3948333_4_20260601T230054Z.jpg | L11: пн 01.06.2026 — 23:00:54 | M11: =HYPERLINK(склад2въезд[[#This Row],[RelativePath]]) -> 1 Въезд на базу\GA3948333_4_20260601T230054Z.jpg | N11: =VLOOKUP(склад2въезд[[#This Row],[Name]], СпрСобытий!$F:$G, 2, FALSE) -> Въезд на базу
A12: вт | B12: 46175 | C12: 0.41518519 | D12: Въезд на базу | E12: Газель базы | I12: GA3948333_4_20260602T095752Z.jpg | J12: C:\ВИДЕОНАБЛЮДЕНИЕ\1 Въезд на базу\ | K12: 1 Въезд на базу\GA3948333_4_20260602T095752Z.jpg | L12: вт 02.06.2026 — 09:57:52 | M12: =HYPERLINK(склад2въезд[[#This Row],[RelativePath]]) -> 1 Въезд на базу\GA3948333_4_20260602T095752Z.jpg | N12: =VLOOKUP(склад2въезд[[#This Row],[Name]], СпрСобытий!$F:$G, 2, FALSE) -> Въезд на базу
A13: вт | B13: 46175 | C13: 0.43984954 | D13: Выезд с территории | E13: Газель базы | I13: GA3948333_4_20260602T103323Z.jpg | J13: C:\ВИДЕОНАБЛЮДЕНИЕ\1 Въезд на базу\ | K13: 1 Въезд на базу\GA3948333_4_20260602T103323Z.jpg | L13: вт 02.06.2026 — 10:33:23 | M13: =HYPERLINK(склад2въезд[[#This Row],[RelativePath]]) -> 1 Въезд на базу\GA3948333_4_20260602T103323Z.jpg | N13: =VLOOKUP(склад2въезд[[#This Row],[Name]], СпрСобытий!$F:$G, 2, FALSE) -> Въезд на базу
A14: вт | B14: 46175 | C14: 0.63920139 | D14: Выезд с территории | E14: Газель базы | I14: GA3948333_4_20260602T152027Z.jpg | J14: C:\ВИДЕОНАБЛЮДЕНИЕ\1 Въезд на базу\ | K14: 1 Въезд на базу\GA3948333_4_20260602T152027Z.jpg | L14: вт 02.06.2026 — 15:20:27 | M14: =HYPERLINK(склад2въезд[[#This Row],[RelativePath]]) -> 1 Въезд на базу\GA3948333_4_20260602T152027Z.jpg | N14: =VLOOKUP(склад2въезд[[#This Row],[Name]], СпрСобытий!$F:$G, 2, FALSE) -> Въезд на базу
A15: ср | B15: 46176 | C15: 0.66898148 | D15: Выезд со второстепенной дороги | E15: Рено логан серый, с прицепом | F15: мешок с опилками | G15: 1 | I15: GA3948333_4_20260603T160320Z.jpg | J15: C:\ВИДЕОНАБЛЮДЕНИЕ\1 Въезд на базу\ | K15: 1 Въезд на базу\GA3948333_4_20260603T160320Z.jpg | L15: ср 03.06.2026 — 16:03:20 | M15: =HYPERLINK(склад2въезд[[#This Row],[RelativePath]]) -> 1 Въезд на базу\GA3948333_4_20260603T160320Z.jpg | N15: =VLOOKUP(склад2въезд[[#This Row],[Name]], СпрСобытий!$F:$G, 2, FALSE) -> Въезд на базу
A16: ср | B16: 46176 | C16: 0.7487963 | D16: Выезд с территории | E16: Камаз базы | F16: порожний | I16: GA3948333_4_20260603T175816Z.jpg | J16: C:\ВИДЕОНАБЛЮДЕНИЕ\1 Въезд на базу\ | K16: 1 Въезд на базу\GA3948333_4_20260603T175816Z.jpg | L16: ср 03.06.2026 — 17:58:16 | M16: =HYPERLINK(склад2въезд[[#This Row],[RelativePath]]) -> 1 Въезд на базу\GA3948333_4_20260603T175816Z.jpg | N16: =VLOOKUP(склад2въезд[[#This Row],[Name]], СпрСобытий!$F:$G, 2, FALSE) -> Въезд на базу
A17: ср | B17: 46176 | C17: 0.83607639 | D17: Въезд на базу | E17: Камаз базы | F17: порожний | I17: GA3948333_4_20260603T200357Z.jpg | J17: C:\ВИДЕОНАБЛЮДЕНИЕ\1 Въезд на базу\ | K17: 1 Въезд на базу\GA3948333_4_20260603T200357Z.jpg | L17: ср 03.06.2026 — 20:03:57 | M17: =HYPERLINK(склад2въезд[[#This Row],[RelativePath]]) -> 1 Въезд на базу\GA3948333_4_20260603T200357Z.jpg | N17: =VLOOKUP(склад2въезд[[#This Row],[Name]], СпрСобытий!$F:$G, 2, FALSE) -> Въезд на базу
A18: чт | B18: 46177 | C18: 0.79237269 | D18: Выезд с территории | E18: Легковая темная | F18: доски | H18: на крыше | I18: GA3948333_4_20260604T190101Z.jpg | J18: C:\ВИДЕОНАБЛЮДЕНИЕ\1 Въезд на базу\ | K18: 1 Въезд на базу\GA3948333_4_20260604T190101Z.jpg | L18: чт 04.06.2026 — 19:01:01 | M18: =HYPERLINK(склад2въезд[[#This Row],[RelativePath]]) -> 1 Въезд на базу\GA3948333_4_20260604T190101Z.jpg | N18: =VLOOKUP(склад2въезд[[#This Row],[Name]], СпрСобытий!$F:$G, 2, FALSE) -> Въезд на базу
A19: пт | B19: 46178 | C19: 0.37186343 | D19: Выезд с территории | E19: Камаз базы | F19: порожний | I19: GA3948333_4_20260605T085529Z.jpg | J19: C:\ВИДЕОНАБЛЮДЕНИЕ\1 Въезд на базу\ | K19: 1 Въезд на базу\GA3948333_4_20260605T085529Z.jpg | L19: пт 05.06.2026 — 08:55:29 | M19: =HYPERLINK(склад2въезд[[#This Row],[RelativePath]]) -> 1 Въезд на базу\GA3948333_4_20260605T085529Z.jpg | N19: =VLOOKUP(склад2въезд[[#This Row],[Name]], СпрСобытий!$F:$G, 2, FALSE) -> Въезд на базу
A20: пт | B20: 46178 | C20: 0.5215162 | D20: Въезд на базу | E20: Камаз базы | F20: порожний | I20: GA3948333_4_20260605T123059Z.jpg | J20: C:\ВИДЕОНАБЛЮДЕНИЕ\1 Въезд на базу\ | K20: 1 Въезд на базу\GA3948333_4_20260605T123059Z.jpg | L20: пт 05.06.2026 — 12:30:59 | M20: =HYPERLINK(склад2въезд[[#This Row],[RelativePath]]) -> 1 Въезд на базу\GA3948333_4_20260605T123059Z.jpg | N20: =VLOOKUP(склад2въезд[[#This Row],[Name]], СпрСобытий!$F:$G, 2, FALSE) -> Въезд на базу
A21: пт | B21: 46178 | C21: 0.52365741 | D21: Выезд с территории | E21: Рено логан серый, с прицепом | F21: дрова под тентом | I21: GA3948333_4_20260605T123404Z.jpg | J21: C:\ВИДЕОНАБЛЮДЕНИЕ\1 Въезд на базу\ | K21: 1 Въезд на базу\GA3948333_4_20260605T123404Z.jpg | L21: пт 05.06.2026 — 12:34:04 | M21: =HYPERLINK(склад2въезд[[#This Row],[RelativePath]]) -> 1 Въезд на базу\GA3948333_4_20260605T123404Z.jpg | N21: =VLOOKUP(склад2въезд[[#This Row],[Name]], СпрСобытий!$F:$G, 2, FALSE) -> Въезд на базу
A22: сб | B22: 46179 | C22: 0.21333333 | D22: Въезд на второстепенную дорогу | E22: Нива, с прицепом | F22: порожний | I22: GA3948333_4_20260606T050712Z.jpg | J22: C:\ВИДЕОНАБЛЮДЕНИЕ\1 Въезд на базу\ | K22: 1 Въезд на базу\GA3948333_4_20260606T050712Z.jpg | L22: сб 06.06.2026 — 05:07:12 | M22: =HYPERLINK(склад2въезд[[#This Row],[RelativePath]]) -> 1 Въезд на базу\GA3948333_4_20260606T050712Z.jpg | N22: =VLOOKUP(склад2въезд[[#This Row],[Name]], СпрСобытий!$F:$G, 2, FALSE) -> Въезд на базу
A23: сб | B23: 46179 | C23: 0.23881944 | D23: Выезд со второстепенной дороги | E23: Нива, с прицепом | F23: доски | I23: GA3948333_4_20260606T054354Z.jpg | J23: C:\ВИДЕОНАБЛЮДЕНИЕ\1 Въезд на базу\ | K23: 1 Въезд на базу\GA3948333_4_20260606T054354Z.jpg | L23: сб 06.06.2026 — 05:43:54 | M23: =HYPERLINK(склад2въезд[[#This Row],[RelativePath]]) -> 1 Въезд на базу\GA3948333_4_20260606T054354Z.jpg | N23: =VLOOKUP(склад2въезд[[#This Row],[Name]], СпрСобытий!$F:$G, 2, FALSE) -> Въезд на базу
A24: сб | B24: 46179 | C24: 0.34143519 | D24: Выезд с территории | E24: Камаз базы | F24: порожний | I24: GA3948333_4_20260606T081140Z.jpg | J24: C:\ВИДЕОНАБЛЮДЕНИЕ\1 Въезд на базу\ | K24: 1 Въезд на базу\GA3948333_4_20260606T081140Z.jpg | L24: сб 06.06.2026 — 08:11:40 | M24: =HYPERLINK(склад2въезд[[#This Row],[RelativePath]]) -> 1 Въезд на базу\GA3948333_4_20260606T081140Z.jpg | N24: =VLOOKUP(склад2въезд[[#This Row],[Name]], СпрСобытий!$F:$G, 2, FALSE) -> Въезд на базу
A25: сб | B25: 46179 | C25: 0.4321412 | D25: Въезд на базу | E25: Камаз базы | F25: порожний | I25: GA3948333_4_20260606T102217Z.jpg | J25: C:\ВИДЕОНАБЛЮДЕНИЕ\1 Въезд на базу\ | K25: 1 Въезд на базу\GA3948333_4_20260606T102217Z.jpg | L25: сб 06.06.2026 — 10:22:17 | M25: =HYPERLINK(склад2въезд[[#This Row],[RelativePath]]) -> 1 Въезд на базу\GA3948333_4_20260606T102217Z.jpg | N25: =VLOOKUP(склад2въезд[[#This Row],[Name]], СпрСобытий!$F:$G, 2, FALSE) -> Въезд на базу
A26: вс | B26: 46180 | C26: 0.4319213 | D26: Въезд на базу | E26: Газель фургон, голубая кабина, серый тент | I26: GA3948333_4_20260607T102158Z.jpg | J26: C:\ВИДЕОНАБЛЮДЕНИЕ\1 Въезд на базу\ | K26: 1 Въезд на базу\GA3948333_4_20260607T102158Z.jpg | L26: вс 07.06.2026 — 10:21:58 | M26: =HYPERLINK(склад2въезд[[#This Row],[RelativePath]]) -> 1 Въезд на базу\GA3948333_4_20260607T102158Z.jpg | N26: =VLOOKUP(склад2въезд[[#This Row],[Name]], СпрСобытий!$F:$G, 2, FALSE) -> Въезд на базу
A27: вс | B27: 46180 | C27: 0.53743056 | D27: Выезд с территории | E27: Газель фургон, голубая кабина, серый тент | I27: GA3948333_4_20260607T125354Z.jpg | J27: C:\ВИДЕОНАБЛЮДЕНИЕ\1 Въезд на базу\ | K27: 1 Въезд на базу\GA3948333_4_20260607T125354Z.jpg | L27: вс 07.06.2026 — 12:53:54 | M27: =HYPERLINK(склад2въезд[[#This Row],[RelativePath]]) -> 1 Въезд на базу\GA3948333_4_20260607T125354Z.jpg | N27: =VLOOKUP(склад2въезд[[#This Row],[Name]], СпрСобытий!$F:$G, 2, FALSE) -> Въезд на базу
A28: вс | B28: 46180 | C28: 0.59016204 | D28: Въезд на базу | E28: Tank 500, серый | I28: GA3948333_4_20260607T140950Z.jpg | J28: C:\ВИДЕОНАБЛЮДЕНИЕ\1 Въезд на базу\ | K28: 1 Въезд на базу\GA3948333_4_20260607T140950Z.jpg | L28: вс 07.06.2026 — 14:09:50 | M28: =HYPERLINK(склад2въезд[[#This Row],[RelativePath]]) -> 1 Въезд на базу\GA3948333_4_20260607T140950Z.jpg | N28: =VLOOKUP(склад2въезд[[#This Row],[Name]], СпрСобытий!$F:$G, 2, FALSE) -> Въезд на базу
A29: вс | B29: 46180 | C29: 0.5962037 | D29: Въезд на второстепенную дорогу | E29: Нива, с прицепом | F29: порожний | I29: GA3948333_4_20260607T141832Z.jpg | J29: C:\ВИДЕОНАБЛЮДЕНИЕ\1 Въезд на базу\ | K29: 1 Въезд на базу\GA3948333_4_20260607T141832Z.jpg | L29: вс 07.06.2026 — 14:18:32 | M29: =HYPERLINK(склад2въезд[[#This Row],[RelativePath]]) -> 1 Въезд на базу\GA3948333_4_20260607T141832Z.jpg | N29: =VLOOKUP(склад2въезд[[#This Row],[Name]], СпрСобытий!$F:$G, 2, FALSE) -> Въезд на базу
A30: вс | B30: 46180 | C30: 0.59684028 | D30: Выезд с территории | E30: Tank 500, серый | I30: GA3948333_4_20260607T141927Z.jpg | J30: C:\ВИДЕОНАБЛЮДЕНИЕ\1 Въезд на базу\ | K30: 1 Въезд на базу\GA3948333_4_20260607T141927Z.jpg | L30: вс 07.06.2026 — 14:19:27 | M30: =HYPERLINK(склад2въезд[[#This Row],[RelativePath]]) -> 1 Въезд на базу\GA3948333_4_20260607T141927Z.jpg | N30: =VLOOKUP(склад2въезд[[#This Row],[Name]], СпрСобытий!$F:$G, 2, FALSE) -> Въезд на базу
A31: вс | B31: 46180 | C31: 0.61918981 | D31: Выезд со второстепенной дороги | E31: Нива, с прицепом | F31: доски | I31: GA3948333_4_20260607T145138Z.jpg | J31: C:\ВИДЕОНАБЛЮДЕНИЕ\1 Въезд на базу\ | K31: 1 Въезд на базу\GA3948333_4_20260607T145138Z.jpg | L31: вс 07.06.2026 — 14:51:38 | M31: =HYPERLINK(склад2въезд[[#This Row],[RelativePath]]) -> 1 Въезд на базу\GA3948333_4_20260607T145138Z.jpg | N31: =VLOOKUP(склад2въезд[[#This Row],[Name]], СпрСобытий!$F:$G, 2, FALSE) -> Въезд на базу
A32: пн | B32: 46181 | C32: 0.30041667 | D32: Въезд на базу | E32: Рено логан серый, с прицепом | F32: порожний | I32: GA3948333_4_20260608T071236Z.jpg | J32: C:\ВИДЕОНАБЛЮДЕНИЕ\1 Въезд на базу\ | K32: 1 Въезд на базу\GA3948333_4_20260608T071236Z.jpg | L32: пн 08.06.2026 — 07:12:36 | M32: =HYPERLINK(склад2въезд[[#This Row],[RelativePath]]) -> 1 Въезд на базу\GA3948333_4_20260608T071236Z.jpg | N32: =VLOOKUP(склад2въезд[[#This Row],[Name]], СпрСобытий!$F:$G, 2, FALSE) -> Въезд на базу
A33: пн | B33: 46181 | C33: 0.3462037 | D33: Выезд с территории | E33: Камаз базы | F33: порожний | I33: GA3948333_4_20260608T081832Z.jpg | J33: C:\ВИДЕОНАБЛЮДЕНИЕ\1 Въезд на базу\ | K33: 1 Въезд на базу\GA3948333_4_20260608T081832Z.jpg | L33: пн 08.06.2026 — 08:18:32 | M33: =HYPERLINK(склад2въезд[[#This Row],[RelativePath]]) -> 1 Въезд на базу\GA3948333_4_20260608T081832Z.jpg | N33: =VLOOKUP(склад2въезд[[#This Row],[Name]], СпрСобытий!$F:$G, 2, FALSE) -> Въезд на базу
A34: пн | B34: 46181 | C34: 0.65746528 | D34: Въезд на базу | E34: Камаз базы | F34: порожний | I34: GA3948333_4_20260608T154645Z.jpg | J34: C:\ВИДЕОНАБЛЮДЕНИЕ\1 Въезд на базу\ | K34: 1 Въезд на базу\GA3948333_4_20260608T154645Z.jpg | L34: пн 08.06.2026 — 15:46:45 | M34: =HYPERLINK(склад2въезд[[#This Row],[RelativePath]]) -> 1 Въезд на базу\GA3948333_4_20260608T154645Z.jpg | N34: =VLOOKUP(склад2въезд[[#This Row],[Name]], СпрСобытий!$F:$G, 2, FALSE) -> Въезд на базу
A35: пн | B35: 46181 | C35: 0.7112037 | D35: Въезд на второстепенную дорогу | E35: Газель, белая кабина, разодранный тент | I35: GA3948333_4_20260608T170408Z.jpg | J35: C:\ВИДЕОНАБЛЮДЕНИЕ\1 Въезд на базу\ | K35: 1 Въезд на базу\GA3948333_4_20260608T170408Z.jpg | L35: пн 08.06.2026 — 17:04:08 | M35: =HYPERLINK(склад2въезд[[#This Row],[RelativePath]]) -> 1 Въезд на базу\GA3948333_4_20260608T170408Z.jpg | N35: =VLOOKUP(склад2въезд[[#This Row],[Name]], СпрСобытий!$F:$G, 2, FALSE) -> Въезд на базу
A36: пн | B36: 46181 | C36: 0.75173611 | D36: Выезд со второстепенной дороги | E36: Газель, белая кабина, разодранный тент | F36: доски | I36: GA3948333_4_20260608T180230Z.jpg | J36: C:\ВИДЕОНАБЛЮДЕНИЕ\1 Въезд на базу\ | K36: 1 Въезд на базу\GA3948333_4_20260608T180230Z.jpg | L36: пн 08.06.2026 — 18:02:30 | M36: =HYPERLINK(склад2въезд[[#This Row],[RelativePath]]) -> 1 Въезд на базу\GA3948333_4_20260608T180230Z.jpg | N36: =VLOOKUP(склад2въезд[[#This Row],[Name]], СпрСобытий!$F:$G, 2, FALSE) -> Въезд на базу
A37: вт | B37: 46182 | C37: 0.53296296 | D37: Въезд на базу | E37: Трактор с ковшом | F37: земля | I37: GA3948333_4_20260609T124728Z.jpg | J37: C:\ВИДЕОНАБЛЮДЕНИЕ\1 Въезд на базу\ | K37: 1 Въезд на базу\GA3948333_4_20260609T124728Z.jpg | L37: вт 09.06.2026 — 12:47:28 | M37: =HYPERLINK(склад2въезд[[#This Row],[RelativePath]]) -> 1 Въезд на базу\GA3948333_4_20260609T124728Z.jpg | N37: =VLOOKUP(склад2въезд[[#This Row],[Name]], СпрСобытий!$F:$G, 2, FALSE) -> Въезд на базу
A38: ср | B38: 46183 | C38: 0.39744213 | D38: Въезд на базу | E38: Лада Гранта | F38: доски | H38: на крыше | I38: GA3948333_4_20260610T093219Z.jpg | J38: C:\ВИДЕОНАБЛЮДЕНИЕ\1 Въезд на базу\ | K38: 1 Въезд на базу\GA3948333_4_20260610T093219Z.jpg | L38: ср 10.06.2026 — 09:32:19 | M38: =HYPERLINK(склад2въезд[[#This Row],[RelativePath]]) -> 1 Въезд на базу\GA3948333_4_20260610T093219Z.jpg | N38: =VLOOKUP(склад2въезд[[#This Row],[Name]], СпрСобытий!$F:$G, 2, FALSE) -> Въезд на базу
A39: ср | B39: 46183 | C39: 0.5956713 | D39: Выезд с территории | E39: Лада Гранта | F39: доски | H39: на крыше | I39: GA3948333_4_20260610T141746Z.jpg | J39: C:\ВИДЕОНАБЛЮДЕНИЕ\1 Въезд на базу\ | K39: 1 Въезд на базу\GA3948333_4_20260610T141746Z.jpg | L39: ср 10.06.2026 — 14:17:46 | M39: =HYPERLINK(склад2въезд[[#This Row],[RelativePath]]) -> 1 Въезд на базу\GA3948333_4_20260610T141746Z.jpg | N39: =VLOOKUP(склад2въезд[[#This Row],[Name]], СпрСобытий!$F:$G, 2, FALSE) -> Въезд на базу
A40: ср | B40: 46183 | C40: 0.76671296 | D40: Выезд с территории | E40: Лада Гранта | F40: доски | H40: на крыше | I40: GA3948333_4_20260610T182404Z.jpg | J40: C:\ВИДЕОНАБЛЮДЕНИЕ\1 Въезд на базу\ | K40: 1 Въезд на базу\GA3948333_4_20260610T182404Z.jpg | L40: ср 10.06.2026 — 18:24:04 | M40: =HYPERLINK(склад2въезд[[#This Row],[RelativePath]]) -> 1 Въезд на базу\GA3948333_4_20260610T182404Z.jpg | N40: =VLOOKUP(склад2въезд[[#This Row],[Name]], СпрСобытий!$F:$G, 2, FALSE) -> Въезд на базу
...

Sheet 2 Поката пилорама
A1: День нед | B1: Дата | C1: Время | D1: Событие | E1: Объект | F1: Груз | G1: Кол-во | H1: Примечание | I1: Name | J1: Folder Path | K1: RelativePath | L1: Подпись | M1: Ссылка на фото
A2: пт | B2: 46171 | C2: 0.490625 | D2: Проезд | E2: Газель фургон, голубая кабина, серый тент | F2: инструменты | I2: GA3948333_8_20260529T114630Z.jpg | J2: C:\ВИДЕОНАБЛЮДЕНИЕ\2 Поката пилорама\ | K2: 2 Поката пилорама\GA3948333_8_20260529T114630Z.jpg | L2: пт 29.05.2026 — 11:46:30 | M2: =HYPERLINK(склад2въезд14[[#This Row],[RelativePath]]) -> 2 Поката пилорама\GA3948333_8_20260529T114630Z.jpg
A3: пт | B3: 46171 | C3: 0.50106481 | D3: Загрузка | E3: Газель фургон, голубая кабина, серый тент | F3: доски | H3: стоит в слепой зоне | I3: GA3948333_8_20260529T120132Z.jpg | J3: C:\ВИДЕОНАБЛЮДЕНИЕ\2 Поката пилорама\ | K3: 2 Поката пилорама\GA3948333_8_20260529T120132Z.jpg | L3: пт 29.05.2026 — 12:01:32 | M3: =HYPERLINK(склад2въезд14[[#This Row],[RelativePath]]) -> 2 Поката пилорама\GA3948333_8_20260529T120132Z.jpg
A4: пт | B4: 46171 | C4: 0.50113426 | D4: Загрузка | E4: Газель фургон, голубая кабина, серый тент | F4: доски | I4: GA3948333_8_20260529T120138Z.jpg | J4: C:\ВИДЕОНАБЛЮДЕНИЕ\2 Поката пилорама\ | K4: 2 Поката пилорама\GA3948333_8_20260529T120138Z.jpg | L4: пт 29.05.2026 — 12:01:38 | M4: =HYPERLINK(склад2въезд14[[#This Row],[RelativePath]]) -> 2 Поката пилорама\GA3948333_8_20260529T120138Z.jpg
A5: пт | B5: 46171 | C5: 0.50116898 | D5: Загрузка | E5: Газель фургон, голубая кабина, серый тент | F5: доски | I5: GA3948333_8_20260529T120141Z.jpg | J5: C:\ВИДЕОНАБЛЮДЕНИЕ\2 Поката пилорама\ | K5: 2 Поката пилорама\GA3948333_8_20260529T120141Z.jpg | L5: пт 29.05.2026 — 12:01:41 | M5: =HYPERLINK(склад2въезд14[[#This Row],[RelativePath]]) -> 2 Поката пилорама\GA3948333_8_20260529T120141Z.jpg
A6: пт | B6: 46171 | C6: 0.51355324 | D6: Загрузка | E6: Газель фургон, голубая кабина, серый тент | F6: доски | I6: GA3948333_8_20260529T121931Z.jpg | J6: C:\ВИДЕОНАБЛЮДЕНИЕ\2 Поката пилорама\ | K6: 2 Поката пилорама\GA3948333_8_20260529T121931Z.jpg | L6: пт 29.05.2026 — 12:19:31 | M6: =HYPERLINK(склад2въезд14[[#This Row],[RelativePath]]) -> 2 Поката пилорама\GA3948333_8_20260529T121931Z.jpg
A7: пт | B7: 46171 | C7: 0.52373843 | D7: Загрузка | E7: Газель фургон, голубая кабина, серый тент | F7: доски | I7: GA3948333_8_20260529T123411Z.jpg | J7: C:\ВИДЕОНАБЛЮДЕНИЕ\2 Поката пилорама\ | K7: 2 Поката пилорама\GA3948333_8_20260529T123411Z.jpg | L7: пт 29.05.2026 — 12:34:11 | M7: =HYPERLINK(склад2въезд14[[#This Row],[RelativePath]]) -> 2 Поката пилорама\GA3948333_8_20260529T123411Z.jpg
A8: пт | B8: 46171 | C8: 0.52903935 | D8: Загрузка | E8: Газель фургон, голубая кабина, серый тент | F8: доски | I8: GA3948333_8_20260529T124149Z.jpg | J8: C:\ВИДЕОНАБЛЮДЕНИЕ\2 Поката пилорама\ | K8: 2 Поката пилорама\GA3948333_8_20260529T124149Z.jpg | L8: пт 29.05.2026 — 12:41:49 | M8: =HYPERLINK(склад2въезд14[[#This Row],[RelativePath]]) -> 2 Поката пилорама\GA3948333_8_20260529T124149Z.jpg
A9: пт | B9: 46171 | C9: 0.69836806 | D9: Проезд | E9: Газель фургон, голубая кабина, серый тент | F9: доски | I9: GA3948333_8_20260529T164539Z.jpg | J9: C:\ВИДЕОНАБЛЮДЕНИЕ\2 Поката пилорама\ | K9: 2 Поката пилорама\GA3948333_8_20260529T164539Z.jpg | L9: пт 29.05.2026 — 16:45:39 | M9: =HYPERLINK(склад2въезд14[[#This Row],[RelativePath]]) -> 2 Поката пилорама\GA3948333_8_20260529T164539Z.jpg
A10: пт | B10: 46171 | C10: 0.69841435 | D10: Проезд | E10: Газель фургон, голубая кабина, серый тент | F10: доски | H10: динамика | I10: GA3948333_8_20260529T164543Z.jpg | J10: C:\ВИДЕОНАБЛЮДЕНИЕ\2 Поката пилорама\ | K10: 2 Поката пилорама\GA3948333_8_20260529T164543Z.jpg | L10: пт 29.05.2026 — 16:45:43 | M10: =HYPERLINK(склад2въезд14[[#This Row],[RelativePath]]) -> 2 Поката пилорама\GA3948333_8_20260529T164543Z.jpg
A11: пт | B11: 46171 | C11: 0.7087037 | D11: Загрузка | E11: Газель фургон, голубая кабина, серый тент | F11: доски | H11: стоит в слепой зоне | I11: GA3948333_8_20260529T170032Z.jpg | J11: C:\ВИДЕОНАБЛЮДЕНИЕ\2 Поката пилорама\ | K11: 2 Поката пилорама\GA3948333_8_20260529T170032Z.jpg | L11: пт 29.05.2026 — 17:00:32 | M11: =HYPERLINK(склад2въезд14[[#This Row],[RelativePath]]) -> 2 Поката пилорама\GA3948333_8_20260529T170032Z.jpg
A12: пт | B12: 46171 | C12: 0.70887731 | D12: Загрузка | E12: Газель фургон, голубая кабина, серый тент | F12: доски | I12: GA3948333_8_20260529T170047Z.jpg | J12: C:\ВИДЕОНАБЛЮДЕНИЕ\2 Поката пилорама\ | K12: 2 Поката пилорама\GA3948333_8_20260529T170047Z.jpg | L12: пт 29.05.2026 — 17:00:47 | M12: =HYPERLINK(склад2въезд14[[#This Row],[RelativePath]]) -> 2 Поката пилорама\GA3948333_8_20260529T170047Z.jpg
A13: пт | B13: 46171 | C13: 0.71196759 | D13: Загрузка | E13: Газель фургон, голубая кабина, серый тент | F13: доски | I13: GA3948333_8_20260529T170514Z.jpg | J13: C:\ВИДЕОНАБЛЮДЕНИЕ\2 Поката пилорама\ | K13: 2 Поката пилорама\GA3948333_8_20260529T170514Z.jpg | L13: пт 29.05.2026 — 17:05:14 | M13: =HYPERLINK(склад2въезд14[[#This Row],[RelativePath]]) -> 2 Поката пилорама\GA3948333_8_20260529T170514Z.jpg
A14: сб | B14: 46172 | C14: 0.78547454 | D14: Убытие | E14: Газель фургон, голубая кабина, серый тент | F14: доски | I14: GA3948333_8_20260530T185105Z.jpg | J14: C:\ВИДЕОНАБЛЮДЕНИЕ\2 Поката пилорама\ | K14: 2 Поката пилорама\GA3948333_8_20260530T185105Z.jpg | L14: сб 30.05.2026 — 18:51:05 | M14: =HYPERLINK(склад2въезд14[[#This Row],[RelativePath]]) -> 2 Поката пилорама\GA3948333_8_20260530T185105Z.jpg
A15: вс | B15: 46173 | C15: 0.76332176 | D15: без событий | E15: Территория | I15: GA3948333_8_20260531T181911Z.jpg | J15: C:\ВИДЕОНАБЛЮДЕНИЕ\2 Поката пилорама\ | K15: 2 Поката пилорама\GA3948333_8_20260531T181911Z.jpg | L15: вс 31.05.2026 — 18:19:11 | M15: =HYPERLINK(склад2въезд14[[#This Row],[RelativePath]]) -> 2 Поката пилорама\GA3948333_8_20260531T181911Z.jpg
A16: пн | B16: 46174 | C16: 0.72412037 | D16: без событий | E16: Территория | I16: GA3948333_8_20260601T172244Z.jpg | J16: C:\ВИДЕОНАБЛЮДЕНИЕ\2 Поката пилорама\ | K16: 2 Поката пилорама\GA3948333_8_20260601T172244Z.jpg | L16: пн 01.06.2026 — 17:22:44 | M16: =HYPERLINK(склад2въезд14[[#This Row],[RelativePath]]) -> 2 Поката пилорама\GA3948333_8_20260601T172244Z.jpg
A17: вт | B17: 46175 | C17: 0.70888889 | D17: без событий | E17: Территория | I17: GA3948333_8_20260602T170048Z.jpg | J17: C:\ВИДЕОНАБЛЮДЕНИЕ\2 Поката пилорама\ | K17: 2 Поката пилорама\GA3948333_8_20260602T170048Z.jpg | L17: вт 02.06.2026 — 17:00:48 | M17: =HYPERLINK(склад2въезд14[[#This Row],[RelativePath]]) -> 2 Поката пилорама\GA3948333_8_20260602T170048Z.jpg
A18: ср | B18: 46176 | C18: 0.66850694 | D18: Проезд | E18: Рено логан серый, с прицепом | F18: мешок с опилками | G18: 1 | I18: GA3948333_8_20260603T160239Z.jpg | J18: C:\ВИДЕОНАБЛЮДЕНИЕ\2 Поката пилорама\ | K18: 2 Поката пилорама\GA3948333_8_20260603T160239Z.jpg | L18: ср 03.06.2026 — 16:02:39 | M18: =HYPERLINK(склад2въезд14[[#This Row],[RelativePath]]) -> 2 Поката пилорама\GA3948333_8_20260603T160239Z.jpg
A19: чт | B19: 46177 | C19: 0.42030093 | D19: Доставка бревна | E19: Трактор базы | G19: 1 | I19: GA3948333_8_20260604T100514Z.jpg | J19: C:\ВИДЕОНАБЛЮДЕНИЕ\2 Поката пилорама\ | K19: 2 Поката пилорама\GA3948333_8_20260604T100514Z.jpg | L19: чт 04.06.2026 — 10:05:14 | M19: =HYPERLINK(склад2въезд14[[#This Row],[RelativePath]]) -> 2 Поката пилорама\GA3948333_8_20260604T100514Z.jpg
A20: чт | B20: 46177 | C20: 0.47967593 | D20: Доставка бревна | E20: Трактор базы | G20: 1 | I20: GA3948333_8_20260604T113044Z.jpg | J20: C:\ВИДЕОНАБЛЮДЕНИЕ\2 Поката пилорама\ | K20: 2 Поката пилорама\GA3948333_8_20260604T113044Z.jpg | L20: чт 04.06.2026 — 11:30:44 | M20: =HYPERLINK(склад2въезд14[[#This Row],[RelativePath]]) -> 2 Поката пилорама\GA3948333_8_20260604T113044Z.jpg
A21: чт | B21: 46177 | C21: 0.68350694 | D21: Доставка бревна | E21: Трактор базы | G21: 1 | I21: GA3948333_8_20260604T162415Z.jpg | J21: C:\ВИДЕОНАБЛЮДЕНИЕ\2 Поката пилорама\ | K21: 2 Поката пилорама\GA3948333_8_20260604T162415Z.jpg | L21: чт 04.06.2026 — 16:24:15 | M21: =HYPERLINK(склад2въезд14[[#This Row],[RelativePath]]) -> 2 Поката пилорама\GA3948333_8_20260604T162415Z.jpg
A22: чт | B22: 46177 | C22: 0.68725694 | D22: Доставка бревна | E22: Трактор базы | G22: 1 | I22: GA3948333_8_20260604T162939Z.jpg | J22: C:\ВИДЕОНАБЛЮДЕНИЕ\2 Поката пилорама\ | K22: 2 Поката пилорама\GA3948333_8_20260604T162939Z.jpg | L22: чт 04.06.2026 — 16:29:39 | M22: =HYPERLINK(склад2въезд14[[#This Row],[RelativePath]]) -> 2 Поката пилорама\GA3948333_8_20260604T162939Z.jpg
A23: чт | B23: 46177 | C23: 0.69127315 | D23: Доставка бревна | E23: Трактор базы | G23: 1 | I23: GA3948333_8_20260604T163526Z.jpg | J23: C:\ВИДЕОНАБЛЮДЕНИЕ\2 Поката пилорама\ | K23: 2 Поката пилорама\GA3948333_8_20260604T163526Z.jpg | L23: чт 04.06.2026 — 16:35:26 | M23: =HYPERLINK(склад2въезд14[[#This Row],[RelativePath]]) -> 2 Поката пилорама\GA3948333_8_20260604T163526Z.jpg
A24: пт | B24: 46178 | C24: 0.37134259 | D24: Доставка отрезка бревна | E24: Трактор базы | G24: 1 | I24: GA3948333_8_20260605T085444Z.jpg | J24: C:\ВИДЕОНАБЛЮДЕНИЕ\2 Поката пилорама\ | K24: 2 Поката пилорама\GA3948333_8_20260605T085444Z.jpg | L24: пт 05.06.2026 — 08:54:44 | M24: =HYPERLINK(склад2въезд14[[#This Row],[RelativePath]]) -> 2 Поката пилорама\GA3948333_8_20260605T085444Z.jpg
A25: пт | B25: 46178 | C25: 0.37472222 | D25: Доставка отрезка бревна | E25: Трактор базы | G25: 1 | I25: GA3948333_8_20260605T085936Z.jpg | J25: C:\ВИДЕОНАБЛЮДЕНИЕ\2 Поката пилорама\ | K25: 2 Поката пилорама\GA3948333_8_20260605T085936Z.jpg | L25: пт 05.06.2026 — 08:59:36 | M25: =HYPERLINK(склад2въезд14[[#This Row],[RelativePath]]) -> 2 Поката пилорама\GA3948333_8_20260605T085936Z.jpg
A26: пт | B26: 46178 | C26: 0.37982639 | D26: Доставка отрезка бревна | E26: Трактор базы | G26: 2 | I26: GA3948333_8_20260605T090657Z.jpg | J26: C:\ВИДЕОНАБЛЮДЕНИЕ\2 Поката пилорама\ | K26: 2 Поката пилорама\GA3948333_8_20260605T090657Z.jpg | L26: пт 05.06.2026 — 09:06:57 | M26: =HYPERLINK(склад2въезд14[[#This Row],[RelativePath]]) -> 2 Поката пилорама\GA3948333_8_20260605T090657Z.jpg
A27: пт | B27: 46178 | C27: 0.38429398 | D27: Доставка отрезка бревна | E27: Трактор базы | G27: 1 | I27: GA3948333_8_20260605T091323Z.jpg | J27: C:\ВИДЕОНАБЛЮДЕНИЕ\2 Поката пилорама\ | K27: 2 Поката пилорама\GA3948333_8_20260605T091323Z.jpg | L27: пт 05.06.2026 — 09:13:23 | M27: =HYPERLINK(склад2въезд14[[#This Row],[RelativePath]]) -> 2 Поката пилорама\GA3948333_8_20260605T091323Z.jpg
A28: сб | B28: 46179 | C28: 0.21457176 | D28: Загрузка | E28: Нива, с прицепом | F28: доски | G28: 2 | I28: GA3948333_8_20260606T050859Z.jpg | J28: C:\ВИДЕОНАБЛЮДЕНИЕ\2 Поката пилорама\ | K28: 2 Поката пилорама\GA3948333_8_20260606T050859Z.jpg | L28: сб 06.06.2026 — 05:08:59 | M28: =HYPERLINK(склад2въезд14[[#This Row],[RelativePath]]) -> 2 Поката пилорама\GA3948333_8_20260606T050859Z.jpg
A29: сб | B29: 46179 | C29: 0.79483796 | D29: без событий | E29: Территория | I29: GA3948333_8_20260606T190434Z.jpg | J29: C:\ВИДЕОНАБЛЮДЕНИЕ\2 Поката пилорама\ | K29: 2 Поката пилорама\GA3948333_8_20260606T190434Z.jpg | L29: сб 06.06.2026 — 19:04:34 | M29: =HYPERLINK(склад2въезд14[[#This Row],[RelativePath]]) -> 2 Поката пилорама\GA3948333_8_20260606T190434Z.jpg
A30: вс | B30: 46180 | C30: 0.59880787 | D30: Загрузка | E30: Нива, с прицепом | F30: доски | I30: GA3948333_8_20260607T142217Z.jpg | J30: C:\ВИДЕОНАБЛЮДЕНИЕ\2 Поката пилорама\ | K30: 2 Поката пилорама\GA3948333_8_20260607T142217Z.jpg | L30: вс 07.06.2026 — 14:22:17 | M30: =HYPERLINK(склад2въезд14[[#This Row],[RelativePath]]) -> 2 Поката пилорама\GA3948333_8_20260607T142217Z.jpg
A31: вс | B31: 46180 | C31: 0.61900463 | D31: Убытие | E31: Нива, с прицепом | F31: доски | I31: GA3948333_8_20260607T145122Z.jpg | J31: C:\ВИДЕОНАБЛЮДЕНИЕ\2 Поката пилорама\ | K31: 2 Поката пилорама\GA3948333_8_20260607T145122Z.jpg | L31: вс 07.06.2026 — 14:51:22 | M31: =HYPERLINK(склад2въезд14[[#This Row],[RelativePath]]) -> 2 Поката пилорама\GA3948333_8_20260607T145122Z.jpg
A32: пн | B32: 46181 | C32: 0.65924769 | D32: Вывоз отрезков бревен | E32: Трактор базы | I32: GA3948333_8_20260608T154919Z.jpg | J32: C:\ВИДЕОНАБЛЮДЕНИЕ\2 Поката пилорама\ | K32: 2 Поката пилорама\GA3948333_8_20260608T154919Z.jpg | L32: пн 08.06.2026 — 15:49:19 | M32: =HYPERLINK(склад2въезд14[[#This Row],[RelativePath]]) -> 2 Поката пилорама\GA3948333_8_20260608T154919Z.jpg
A33: пн | B33: 46181 | C33: 0.65944444 | D33: Вывоз отрезков бревен | E33: Трактор базы | H33: динамика | I33: GA3948333_8_20260608T154936Z.jpg | J33: C:\ВИДЕОНАБЛЮДЕНИЕ\2 Поката пилорама\ | K33: 2 Поката пилорама\GA3948333_8_20260608T154936Z.jpg | L33: пн 08.06.2026 — 15:49:36 | M33: =HYPERLINK(склад2въезд14[[#This Row],[RelativePath]]) -> 2 Поката пилорама\GA3948333_8_20260608T154936Z.jpg
A34: пн | B34: 46181 | C34: 0.72944444 | D34: Загрузка | E34: Газель, белая кабина, разодранный тент | F34: доски | I34: GA3948333_8_20260608T173024Z.jpg | J34: C:\ВИДЕОНАБЛЮДЕНИЕ\2 Поката пилорама\ | K34: 2 Поката пилорама\GA3948333_8_20260608T173024Z.jpg | L34: пн 08.06.2026 — 17:30:24 | M34: =HYPERLINK(склад2въезд14[[#This Row],[RelativePath]]) -> 2 Поката пилорама\GA3948333_8_20260608T173024Z.jpg
A35: пн | B35: 46181 | C35: 0.73622685 | D35: Загрузка | E35: Газель, белая кабина, разодранный тент | F35: доски | I35: GA3948333_8_20260608T174010Z.jpg | J35: C:\ВИДЕОНАБЛЮДЕНИЕ\2 Поката пилорама\ | K35: 2 Поката пилорама\GA3948333_8_20260608T174010Z.jpg | L35: пн 08.06.2026 — 17:40:10 | M35: =HYPERLINK(склад2въезд14[[#This Row],[RelativePath]]) -> 2 Поката пилорама\GA3948333_8_20260608T174010Z.jpg
A36: вт | B36: 46182 | C36: 0.85945602 | D36: без событий | E36: Территория | I36: GA3948333_8_20260609T203737Z.jpg | J36: C:\ВИДЕОНАБЛЮДЕНИЕ\2 Поката пилорама\ | K36: 2 Поката пилорама\GA3948333_8_20260609T203737Z.jpg | L36: вт 09.06.2026 — 20:37:37 | M36: =HYPERLINK(склад2въезд14[[#This Row],[RelativePath]]) -> 2 Поката пилорама\GA3948333_8_20260609T203737Z.jpg
A37: ср | B37: 46183 | C37: 0.75836806 | D37: без событий | E37: Территория | I37: GA3948333_8_20260610T181203Z.jpg | J37: C:\ВИДЕОНАБЛЮДЕНИЕ\2 Поката пилорама\ | K37: 2 Поката пилорама\GA3948333_8_20260610T181203Z.jpg | L37: ср 10.06.2026 — 18:12:03 | M37: =HYPERLINK(склад2въезд14[[#This Row],[RelativePath]]) -> 2 Поката пилорама\GA3948333_8_20260610T181203Z.jpg
A38: чт | B38: 46184 | C38: 0.76078704 | D38: без событий | E38: Территория | I38: GA3948333_8_20260611T181532Z.jpg | J38: C:\ВИДЕОНАБЛЮДЕНИЕ\2 Поката пилорама\ | K38: 2 Поката пилорама\GA3948333_8_20260611T181532Z.jpg | L38: чт 11.06.2026 — 18:15:32 | M38: =HYPERLINK(склад2въезд14[[#This Row],[RelativePath]]) -> 2 Поката пилорама\GA3948333_8_20260611T181532Z.jpg
A39: пт | B39: 46185 | C39: 0.25349537 | D39: Проезд | E39: Нива, с прицепом | F39: порожний | I39: GA3948333_8_20260612T060502Z.jpg | J39: C:\ВИДЕОНАБЛЮДЕНИЕ\2 Поката пилорама\ | K39: 2 Поката пилорама\GA3948333_8_20260612T060502Z.jpg | L39: пт 12.06.2026 — 06:05:02 | M39: =HYPERLINK(склад2въезд14[[#This Row],[RelativePath]]) -> 2 Поката пилорама\GA3948333_8_20260612T060502Z.jpg
A40: пт | B40: 46185 | C40: 0.26603009 | D40: Обратный проезд | E40: Нива, с прицепом | F40: доски | I40: GA3948333_8_20260612T062305Z.jpg | J40: C:\ВИДЕОНАБЛЮДЕНИЕ\2 Поката пилорама\ | K40: 2 Поката пилорама\GA3948333_8_20260612T062305Z.jpg | L40: пт 12.06.2026 — 06:23:05 | M40: =HYPERLINK(склад2въезд14[[#This Row],[RelativePath]]) -> 2 Поката пилорама\GA3948333_8_20260612T062305Z.jpg
...

Sheet 3 Парковка офиса
A1: День нед | B1: Дата | C1: Время | D1: Событие | E1: Объект | F1: Груз | G1: Кол-во | H1: Примечание | I1: Name | J1: Folder Path | K1: RelativePath | L1: Подпись | M1: Ссылка на фото
A2: пт | B2: 46171 | C2: 0.39282407 | D2: Стоянка | E2: Легковая, темная | H2: только заехал на базу и выехал | I2: GA3948333_3_20260529T092540Z.jpg | J2: C:\ВИДЕОНАБЛЮДЕНИЕ\3 Парковка офиса\ | K2: 3 Парковка офиса\GA3948333_3_20260529T092540Z.jpg | L2: пт 29.05.2026 — 09:25:40 | M2: =HYPERLINK(склад2въезд18[[#This Row],[RelativePath]]) -> 3 Парковка офиса\GA3948333_3_20260529T092540Z.jpg
A3: пт | B3: 46171 | C3: 0.60517361 | D3: Фиксация в кадре | E3: Автотранспорт | I3: GA3948333_3_20260529T143127Z.jpg | J3: C:\ВИДЕОНАБЛЮДЕНИЕ\3 Парковка офиса\ | K3: 3 Парковка офиса\GA3948333_3_20260529T143127Z.jpg | L3: пт 29.05.2026 — 14:31:27 | M3: =HYPERLINK(склад2въезд18[[#This Row],[RelativePath]]) -> 3 Парковка офиса\GA3948333_3_20260529T143127Z.jpg
A4: сб | B4: 46172 | C4: 0.41248843 | D4: Фиксация в кадре | E4: Территория | I4: GA3948333_3_20260530T095359Z.jpg | J4: C:\ВИДЕОНАБЛЮДЕНИЕ\3 Парковка офиса\ | K4: 3 Парковка офиса\GA3948333_3_20260530T095359Z.jpg | L4: сб 30.05.2026 — 09:53:59 | M4: =HYPERLINK(склад2въезд18[[#This Row],[RelativePath]]) -> 3 Парковка офиса\GA3948333_3_20260530T095359Z.jpg
A5: вс | B5: 46173 | C5: 0.82892361 | D5: без событий | E5: Территория | I5: GA3948333_3_20260531T195339Z.jpg | J5: C:\ВИДЕОНАБЛЮДЕНИЕ\3 Парковка офиса\ | K5: 3 Парковка офиса\GA3948333_3_20260531T195339Z.jpg | L5: вс 31.05.2026 — 19:53:39 | M5: =HYPERLINK(склад2въезд18[[#This Row],[RelativePath]]) -> 3 Парковка офиса\GA3948333_3_20260531T195339Z.jpg
A6: пн | B6: 46174 | C6: 0.41916667 | D6: Фиксация в кадре | E6: Автотранспорт | I6: GA3948333_3_20260601T100336Z.jpg | J6: C:\ВИДЕОНАБЛЮДЕНИЕ\3 Парковка офиса\ | K6: 3 Парковка офиса\GA3948333_3_20260601T100336Z.jpg | L6: пн 01.06.2026 — 10:03:36 | M6: =HYPERLINK(склад2въезд18[[#This Row],[RelativePath]]) -> 3 Парковка офиса\GA3948333_3_20260601T100336Z.jpg
A7: пн | B7: 46174 | C7: 0.53236111 | D7: Фиксация в кадре | E7: Автотранспорт | I7: GA3948333_3_20260601T124636Z.jpg | J7: C:\ВИДЕОНАБЛЮДЕНИЕ\3 Парковка офиса\ | K7: 3 Парковка офиса\GA3948333_3_20260601T124636Z.jpg | L7: пн 01.06.2026 — 12:46:36 | M7: =HYPERLINK(склад2въезд18[[#This Row],[RelativePath]]) -> 3 Парковка офиса\GA3948333_3_20260601T124636Z.jpg
A8: пн | B8: 46174 | C8: 0.77243056 | D8: Убытие | E8: Камаз базы | I8: GA3948333_3_20260601T183218Z.jpg | J8: C:\ВИДЕОНАБЛЮДЕНИЕ\3 Парковка офиса\ | K8: 3 Парковка офиса\GA3948333_3_20260601T183218Z.jpg | L8: пн 01.06.2026 — 18:32:18 | M8: =HYPERLINK(склад2въезд18[[#This Row],[RelativePath]]) -> 3 Парковка офиса\GA3948333_3_20260601T183218Z.jpg
A9: пн | B9: 46174 | C9: 0.82825231 | D9: Фиксация в кадре | E9: Автотранспорт | I9: GA3948333_3_20260601T195241Z.jpg | J9: C:\ВИДЕОНАБЛЮДЕНИЕ\3 Парковка офиса\ | K9: 3 Парковка офиса\GA3948333_3_20260601T195241Z.jpg | L9: пн 01.06.2026 — 19:52:41 | M9: =HYPERLINK(склад2въезд18[[#This Row],[RelativePath]]) -> 3 Парковка офиса\GA3948333_3_20260601T195241Z.jpg
A10: вт | B10: 46175 | C10: 0.42565972 | D10: Фиксация в кадре | E10: Автотранспорт | I10: GA3948333_3_20260602T101257Z.jpg | J10: C:\ВИДЕОНАБЛЮДЕНИЕ\3 Парковка офиса\ | K10: 3 Парковка офиса\GA3948333_3_20260602T101257Z.jpg | L10: вт 02.06.2026 — 10:12:57 | M10: =HYPERLINK(склад2въезд18[[#This Row],[RelativePath]]) -> 3 Парковка офиса\GA3948333_3_20260602T101257Z.jpg
A11: вт | B11: 46175 | C11: 0.43658565 | D11: Фиксация в кадре | E11: Автотранспорт | I11: GA3948333_3_20260602T102841Z.jpg | J11: C:\ВИДЕОНАБЛЮДЕНИЕ\3 Парковка офиса\ | K11: 3 Парковка офиса\GA3948333_3_20260602T102841Z.jpg | L11: вт 02.06.2026 — 10:28:41 | M11: =HYPERLINK(склад2въезд18[[#This Row],[RelativePath]]) -> 3 Парковка офиса\GA3948333_3_20260602T102841Z.jpg
A12: вт | B12: 46175 | C12: 0.46409722 | D12: Фиксация в кадре | E12: Автотранспорт | I12: GA3948333_3_20260602T110818Z.jpg | J12: C:\ВИДЕОНАБЛЮДЕНИЕ\3 Парковка офиса\ | K12: 3 Парковка офиса\GA3948333_3_20260602T110818Z.jpg | L12: вт 02.06.2026 — 11:08:18 | M12: =HYPERLINK(склад2въезд18[[#This Row],[RelativePath]]) -> 3 Парковка офиса\GA3948333_3_20260602T110818Z.jpg
A13: вт | B13: 46175 | C13: 0.63300926 | D13: Фиксация в кадре | E13: Автотранспорт | I13: GA3948333_3_20260602T151132Z.jpg | J13: C:\ВИДЕОНАБЛЮДЕНИЕ\3 Парковка офиса\ | K13: 3 Парковка офиса\GA3948333_3_20260602T151132Z.jpg | L13: вт 02.06.2026 — 15:11:32 | M13: =HYPERLINK(склад2въезд18[[#This Row],[RelativePath]]) -> 3 Парковка офиса\GA3948333_3_20260602T151132Z.jpg
A14: ср | B14: 46176 | C14: 0.46217593 | D14: Фиксация в кадре | E14: Автотранспорт | I14: GA3948333_3_20260603T110532Z.jpg | J14: C:\ВИДЕОНАБЛЮДЕНИЕ\3 Парковка офиса\ | K14: 3 Парковка офиса\GA3948333_3_20260603T110532Z.jpg | L14: ср 03.06.2026 — 11:05:32 | M14: =HYPERLINK(склад2въезд18[[#This Row],[RelativePath]]) -> 3 Парковка офиса\GA3948333_3_20260603T110532Z.jpg
... A23: вс | B23: 46180 | C23: 0.59064815 | D23: Стоянка | E23: Tank 500, серый | I23: GA3948333_3_20260607T141032Z.jpg | J23: C:\ВИДЕОНАБЛЮДЕНИЕ\3 Парковка офиса\ | K23: 3 Парковка офиса\GA3948333_3_20260607T141032Z.jpg | L23: вс 07.06.2026 — 14:10:32 | M23: =HYPERLINK(склад2въезд18[[#This Row],[RelativePath]]) -> 3 Парковка офиса\GA3948333_3_20260607T141032Z.jpg
A24: вс | B24: 46180 | C24: 0.6334838 | D24: Фиксация в кадре | E24: Сотрудник с тачкой | F24: ведра, материалы | H24: в общагу | I24: GA3948333_3_20260607T151213Z.jpg | J24: C:\ВИДЕОНАБЛЮДЕНИЕ\3 Парковка офиса\ | K24: 3 Парковка офиса\GA3948333_3_20260607T151213Z.jpg | L24: вс 07.06.2026 — 15:12:13 | M24: =HYPERLINK(склад2въезд18[[#This Row],[RelativePath]]) -> 3 Парковка офиса\GA3948333_3_20260607T151213Z.jpg
A25: пн | B25: 46181 | C25: 0.40773148 | D25: Фиксация в кадре | E25: Автотранспорт | I25: GA3948333_3_20260608T094708Z.jpg | J25: C:\ВИДЕОНАБЛЮДЕНИЕ\3 Парковка офиса\ | K25: 3 Парковка офиса\GA3948333_3_20260608T094708Z.jpg | L25: пн 08.06.2026 — 09:47:08 | M25: =HYPERLINK(склад2въезд18[[#This Row],[RelativePath]]) -> 3 Парковка офиса\GA3948333_3_20260608T094708Z.jpg
A26: пн | B26: 46181 | C26: 0.4324537 | D26: Фиксация в кадре | E26: Автотранспорт | I26: GA3948333_3_20260608T102244Z.jpg | J26: C:\ВИДЕОНАБЛЮДЕНИЕ\3 Парковка офиса\ | K26: 3 Парковка офиса\GA3948333_3_20260608T102244Z.jpg | L26: пн 08.06.2026 — 10:22:44 | M26: =HYPERLINK(склад2въезд18[[#This Row],[RelativePath]]) -> 3 Парковка офиса\GA3948333_3_20260608T102244Z.jpg
A27: пн | B27: 46181 | C27: 0.65334491 | D27: Фиксация в кадре | E27: Автотранспорт | I27: GA3948333_3_20260608T154049Z.jpg | J27: C:\ВИДЕОНАБЛЮДЕНИЕ\3 Парковка офиса\ | K27: 3 Парковка офиса\GA3948333_3_20260608T154049Z.jpg | L27: пн 08.06.2026 — 15:40:49 | M27: =HYPERLINK(склад2въезд18[[#This Row],[RelativePath]]) -> 3 Парковка офиса\GA3948333_3_20260608T154049Z.jpg
A28: вт | B28: 46182 | C28: 0.67215278 | D28: Фиксация в кадре | E28: Автотранспорт | I28: GA3948333_3_20260609T160754Z.jpg | J28: C:\ВИДЕОНАБЛЮДЕНИЕ\3 Парковка офиса\ | K28: 3 Парковка офиса\GA3948333_3_20260609T160754Z.jpg | L28: вт 09.06.2026 — 16:07:54 | M28: =HYPERLINK(склад2въезд18[[#This Row],[RelativePath]]) -> 3 Парковка офиса\GA3948333_3_20260609T160754Z.jpg
A29: ср | B29: 46183 | C29: 0.47121528 | D29: Фиксация в кадре | E29: Автотранспорт | I29: GA3948333_3_20260610T111833Z.jpg | J29: C:\ВИДЕОНАБЛЮДЕНИЕ\3 Парковка офиса\ | K29: 3 Парковка офиса\GA3948333_3_20260610T111833Z.jpg | L29: ср 10.06.2026 — 11:18:33 | M29: =HYPERLINK(склад2въезд18[[#This Row],[RelativePath]]) -> 3 Парковка офиса\GA3948333_3_20260610T111833Z.jpg
A30: ср | B30: 46183 | C30: 0.63895833 | D30: Фиксация в кадре | E30: Автотранспорт | I30: GA3948333_3_20260610T152006Z.jpg | J30: C:\ВИДЕОНАБЛЮДЕНИЕ\3 Парковка офиса\ | K30: 3 Парковка офиса\GA3948333_3_20260610T152006Z.jpg | L30: ср 10.06.2026 — 15:20:06 | M30: =HYPERLINK(склад2въезд18[[#This Row],[RelativePath]]) -> 3 Парковка офиса\GA3948333_3_20260610T152006Z.jpg
A31: ср | B31: 46183 | C31: 0.77903935 | D31: Смена ракурса камер | I31: GA3948333_3_20260610T184149Z.jpg | J31: C:\ВИДЕОНАБЛЮДЕНИЕ\3 Парковка офиса\ | K31: 3 Парковка офиса\GA3948333_3_20260610T184149Z.jpg | L31: ср 10.06.2026 — 18:41:49 | M31: =HYPERLINK(склад2въезд18[[#This Row],[RelativePath]]) -> 3 Парковка офиса\GA3948333_3_20260610T184149Z.jpg
A32: чт | B32: 46184 | C32: 0.46556713 | D32: Загрузка | E32: Рено Колеос | F32: дрова | I32: GA3948333_3_20260611T111025Z.jpg | J32: C:\ВИДЕОНАБЛЮДЕНИЕ\3 Парковка офиса\ | K32: 3 Парковка офиса\GA3948333_3_20260611T111025Z.jpg | L32: чт 11.06.2026 — 11:10:25 | M32: =HYPERLINK(склад2въезд18[[#This Row],[RelativePath]]) -> 3 Парковка офиса\GA3948333_3_20260611T111025Z.jpg
A33: чт | B33: 46184 | C33: 0.46636574 | D33: Загрузка | E33: Рено Колеос | F33: дрова | I33: GA3948333_3_20260611T111134Z.jpg | J33: C:\ВИДЕОНАБЛЮДЕНИЕ\3 Парковка офиса\ | K33: 3 Парковка офиса\GA3948333_3_20260611T111134Z.jpg | L33: чт 11.06.2026 — 11:11:34 | M33: =HYPERLINK(склад2въезд18[[#This Row],[RelativePath]]) -> 3 Парковка офиса\GA3948333_3_20260611T111134Z.jpg
A34: чт | B34: 46184 | C34: 0.52216435 | D34: Фиксация в кадре | E34: Автотранспорт | I34: GA3948333_3_20260611T123155Z.jpg | J34: C:\ВИДЕОНАБЛЮДЕНИЕ\3 Парковка офиса\ | K34: 3 Парковка офиса\GA3948333_3_20260611T123155Z.jpg | L34: чт 11.06.2026 — 12:31:55 | M34: =HYPERLINK(склад2въезд18[[#This Row],[RelativePath]]) -> 3 Парковка офиса\GA3948333_3_20260611T123155Z.jpg
A35: чт | B35: 46184 | C35: 0.58663194 | D35: Фиксация в кадре | E35: Автотранспорт | I35: GA3948333_3_20260611T140445Z.jpg | J35: C:\ВИДЕОНАБЛЮДЕНИЕ\3 Парковка офиса\ | K35: 3 Парковка офиса\GA3948333_3_20260611T140445Z.jpg | L35: чт 11.06.2026 — 14:04:45 | M35: =HYPERLINK(склад2въезд18[[#This Row],[RelativePath]]) -> 3 Парковка офиса\GA3948333_3_20260611T140445Z.jpg
A36: пт | B36: 46185 | C36: 0.58646991 | D36: без событий | E36: Территория | I36: GA3948333_3_20260612T140431Z.jpg | J36: C:\ВИДЕОНАБЛЮДЕНИЕ\3 Парковка офиса\ | K36: 3 Парковка офиса\GA3948333_3_20260612T140431Z.jpg | L36: пт 12.06.2026 — 14:04:31 | M36: =HYPERLINK(склад2въезд18[[#This Row],[RelativePath]]) -> 3 Парковка офиса\GA3948333_3_20260612T140431Z.jpg
A37: сб | B37: 46186 | C37: 0.65898148 | D37: без событий | E37: Территория | I37: GA3948333_3_20260613T154856Z.jpg | J37: C:\ВИДЕОНАБЛЮДЕНИЕ\3 Парковка офиса\ | K37: 3 Парковка офиса\GA3948333_3_20260613T154856Z.jpg | L37: сб 13.06.2026 — 15:48:56 | M37: =HYPERLINK(склад2въезд18[[#This Row],[RelativePath]]) -> 3 Парковка офиса\GA3948333_3_20260613T154856Z.jpg
A38: вс | B38: 46187 | C38: 0.71334491 | D38: без событий | E38: Территория | I38: GA3948333_3_20260614T170713Z.jpg | J38: C:\ВИДЕОНАБЛЮДЕНИЕ\3 Парковка офиса\ | K38: 3 Парковка офиса\GA3948333_3_20260614T170713Z.jpg | L38: вс 14.06.2026 — 17:07:13 | M38: =HYPERLINK(склад2въезд18[[#This Row],[RelativePath]]) -> 3 Парковка офиса\GA3948333_3_20260614T170713Z.jpg
A39: пн | B39: 46188 | C39: 0.39185185 | D39: Фиксация в кадре | E39: Автотранспорт | I39: GA3948333_3_20260615T092416Z.jpg | J39: C:\ВИДЕОНАБЛЮДЕНИЕ\3 Парковка офиса\ | K39: 3 Парковка офиса\GA3948333_3_20260615T092416Z.jpg | L39: пн 15.06.2026 — 09:24:16 | M39: =HYPERLINK(склад2въезд18[[#This Row],[RelativePath]]) -> 3 Парковка офиса\GA3948333_3_20260615T092416Z.jpg
A40: пн | B40: 46188 | C40: 0.4362963 | D40: Фиксация в кадре | E40: Автотранспорт | I40: GA3948333_3_20260615T102816Z.jpg | J40: C:\ВИДЕОНАБЛЮДЕНИЕ\3 Парковка офиса\ | K40: 3 Парковка офиса\GA3948333_3_20260615T102816Z.jpg | L40: пн 15.06.2026 — 10:28:16 | M40: =HYPERLINK(склад2въезд18[[#This Row],[RelativePath]]) -> 3 Парковка офиса\GA3948333_3_20260615T102816Z.jpg
A41: пн | B41: 46188 | C41: 0.54103009 | D41: Фиксация в кадре | E41: Автотранспорт | I41: GA3948333_3_20260615T125905Z.jpg | J41: C:\ВИДЕОНАБЛЮДЕНИЕ\3 Парковка офиса\ | K41: 3 Парковка офиса\GA3948333_3_20260615T125905Z.jpg | L41: пн 15.06.2026 — 12:59:05 | M41: =HYPERLINK(склад2въезд18[[#This Row],[RelativePath]]) -> 3 Парковка офиса\GA3948333_3_20260615T125905Z.jpg
A42: пн | B42: 46188 | C42: 0.56490741 | D42: Загрузка | E42: Рено Колеос | F42: дрова | I42: GA3948333_3_20260615T133328Z.jpg | J42: C:\ВИДЕОНАБЛЮДЕНИЕ\3 Парковка офиса\ | K42: 3 Парковка офиса\GA3948333_3_20260615T133328Z.jpg | L42: пн 15.06.2026 — 13:33:28 | M42: =HYPERLINK(склад2въезд18[[#This Row],[RelativePath]]) -> 3 Парковка офиса\GA3948333_3_20260615T133328Z.jpg
A43: пн | B43: 46188 | C43: 0.60549769 | D43: Загрузка | E43: Рено логан серый, с прицепом | G43: 2 | I43: GA3948333_3_20260615T143155Z.jpg | J43: C:\ВИДЕОНАБЛЮДЕНИЕ\3 Парковка офиса\ | K43: 3 Парковка офиса\GA3948333_3_20260615T143155Z.jpg | L43: пн 15.06.2026 — 14:31:55 | M43: =HYPERLINK(склад2въезд18[[#This Row],[RelativePath]]) -> 3 Парковка офиса\GA3948333_3_20260615T143155Z.jpg
A44: пн | B44: 46188 | C44: 0.62862269 | D44: Выгрузка | E44: Рено логан серый, с прицепом | G44: 2 | I44: GA3948333_3_20260615T150513Z.jpg | J44: C:\ВИДЕОНАБЛЮДЕНИЕ\3 Парковка офиса\ | K44: 3 Парковка офиса\GA3948333_3_20260615T150513Z.jpg | L44: пн 15.06.2026 — 15:05:13 | M44: =HYPERLINK(склад2въезд18[[#This Row],[RelativePath]]) -> 3 Парковка офиса\GA3948333_3_20260615T150513Z.jpg
A45: пн | B45: 46188 | C45: 0.65493056 | D45: Фиксация в кадре | E45: Автотранспорт | I45: GA3948333_3_20260615T154306Z.jpg | J45: C:\ВИДЕОНАБЛЮДЕНИЕ\3 Парковка офиса\ | K45: 3 Парковка офиса\GA3948333_3_20260615T154306Z.jpg | L45: пн 15.06.2026 — 15:43:06 | M45: =HYPERLINK(склад2въезд18[[#This Row],[RelativePath]]) -> 3 Парковка офиса\GA3948333_3_20260615T154306Z.jpg
A46: вт | B46: 46189 | C46: 0.46534722 | D46: Фиксация в кадре | E46: Автотранспорт | I46: GA3948333_3_20260616T111006Z.jpg | J46: C:\ВИДЕОНАБЛЮДЕНИЕ\3 Парковка офиса\ | K46: 3 Парковка офиса\GA3948333_3_20260616T111006Z.jpg | L46: вт 16.06.2026 — 11:10:06 | M46: =HYPERLINK(склад2въезд18[[#This Row],[RelativePath]]) -> 3 Парковка офиса\GA3948333_3_20260616T111006Z.jpg
A47: вт | B47: 46189 | C47: 0.50571759 | D47: Фиксация в кадре | E47: Автотранспорт | I47: GA3948333_3_20260616T120814Z.jpg | J47: C:\ВИДЕОНАБЛЮДЕНИЕ\3 Парковка офиса\ | K47: 3 Парковка офиса\GA3948333_3_20260616T120814Z.jpg | L47: вт 16.06.2026 — 12:08:14 | M47: =HYPERLINK(склад2въезд18[[#This Row],[RelativePath]]) -> 3 Парковка офиса\GA3948333_3_20260616T120814Z.jpg
A48: вт | B48: 46189 | C48: 0.55332176 | D48: Фиксация в кадре | E48: Автотранспорт | I48: GA3948333_3_20260616T131647Z.jpg | J48: C:\ВИДЕОНАБЛЮДЕНИЕ\3 Парковка офиса\ | K48: 3 Парковка офиса\GA3948333_3_20260616T131647Z.jpg | L48: вт 16.06.2026 — 13:16:47 | M48: =HYPERLINK(склад2въезд18[[#This Row],[RelativePath]]) -> 3 Парковка офиса\GA3948333_3_20260616T131647Z.jpg
...

Sheet 4 Крыльцо офиса
A1: День нед | B1: Дата | C1: Время | D1: Событие | E1: Объект | F1: Груз | G1: Кол-во | H1: Примечание | I1: Name | J1: Folder Path | K1: RelativePath | L1: Подпись | M1: Ссылка на фото
A2: пт | B2: 46171 | C2: 0.38454861 | D2: без событий | E2: Территория | I2: K07156189_21_20260529T091345Z.jpg | J2: C:\ВИДЕОНАБЛЮДЕНИЕ\4 Крыльцо офиса\ | K2: 4 Крыльцо офиса\K07156189_21_20260529T091345Z.jpg | L2: пт 29.05.2026 — 09:13:45 | M2: =HYPERLINK(склад2въезд13[[#This Row],[RelativePath]]) -> 4 Крыльцо офиса\K07156189_21_20260529T091345Z.jpg
A3: пт | B3: 46171 | C3: 0.48114583 | D3: Фиксация в кадре | E3: Автотранспорт | I3: K07156189_21_20260529T113251Z.jpg | J3: C:\ВИДЕОНАБЛЮДЕНИЕ\4 Крыльцо офиса\ | K3: 4 Крыльцо офиса\K07156189_21_20260529T113251Z.jpg | L3: пт 29.05.2026 — 11:32:51 | M3: =HYPERLINK(склад2въезд13[[#This Row],[RelativePath]]) -> 4 Крыльцо офиса\K07156189_21_20260529T113251Z.jpg
A4: пт | B4: 46171 | C4: 0.53555556 | D4: Фиксация в кадре | E4: Автотранспорт | I4: K07156189_21_20260529T125112Z.jpg | J4: C:\ВИДЕОНАБЛЮДЕНИЕ\4 Крыльцо офиса\ | K4: 4 Крыльцо офиса\K07156189_21_20260529T125112Z.jpg | L4: пт 29.05.2026 — 12:51:12 | M4: =HYPERLINK(склад2въезд13[[#This Row],[RelativePath]]) -> 4 Крыльцо офиса\K07156189_21_20260529T125112Z.jpg
A5: пт | B5: 46171 | C5: 0.56240741 | D5: Разгрузка | E5: Легковая темная | F5: материалы | I5: K07156189_21_20260529T132952Z.jpg | J5: C:\ВИДЕОНАБЛЮДЕНИЕ\4 Крыльцо офиса\ | K5: 4 Крыльцо офиса\K07156189_21_20260529T132952Z.jpg | L5: пт 29.05.2026 — 13:29:52 | M5: =HYPERLINK(склад2въезд13[[#This Row],[RelativePath]]) -> 4 Крыльцо офиса\K07156189_21_20260529T132952Z.jpg
A6: пт | B6: 46171 | C6: 0.56259259 | D6: Разгрузка | E6: Легковая темная | F6: агрегат | I6: K07156189_21_20260529T133008Z.jpg | J6: C:\ВИДЕОНАБЛЮДЕНИЕ\4 Крыльцо офиса\ | K6: 4 Крыльцо офиса\K07156189_21_20260529T133008Z.jpg | L6: пт 29.05.2026 — 13:30:08 | M6: =HYPERLINK(склад2въезд13[[#This Row],[RelativePath]]) -> 4 Крыльцо офиса\K07156189_21_20260529T133008Z.jpg
A7: пт | B7: 46171 | C7: 0.61592593 | D7: Перемещение материалов | E7: Сотрудник | I7: K07156189_21_20260529T144656Z.jpg | J7: C:\ВИДЕОНАБЛЮДЕНИЕ\4 Крыльцо офиса\ | K7: 4 Крыльцо офиса\K07156189_21_20260529T144656Z.jpg | L7: пт 29.05.2026 — 14:46:56 | M7: =HYPERLINK(склад2въезд13[[#This Row],[RelativePath]]) -> 4 Крыльцо офиса\K07156189_21_20260529T144656Z.jpg
A8: пт | B8: 46171 | C8: 0.61834491 | D8: Перемещение агрегата | E8: Сотрудник | I8: K07156189_21_20260529T145025Z.jpg | J8: C:\ВИДЕОНАБЛЮДЕНИЕ\4 Крыльцо офиса\ | K8: 4 Крыльцо офиса\K07156189_21_20260529T145025Z.jpg | L8: пт 29.05.2026 — 14:50:25 | M8: =HYPERLINK(склад2въезд13[[#This Row],[RelativePath]]) -> 4 Крыльцо офиса\K07156189_21_20260529T145025Z.jpg
A9: сб | B9: 46172 | C9: 0.4134838 | D9: без событий | E9: Территория | I9: K07156189_21_20260530T095525Z.jpg | J9: C:\ВИДЕОНАБЛЮДЕНИЕ\4 Крыльцо офиса\ | K9: 4 Крыльцо офиса\K07156189_21_20260530T095525Z.jpg | L9: сб 30.05.2026 — 09:55:25 | M9: =HYPERLINK(склад2въезд13[[#This Row],[RelativePath]]) -> 4 Крыльцо офиса\K07156189_21_20260530T095525Z.jpg
A10: сб | B10: 46172 | C10: 0.41356481 | D10: Загрузка | E10: Легковая серая | F10: шланг | H10: из камаза базы | I10: K07156189_21_20260530T095532Z.jpg | J10: C:\ВИДЕОНАБЛЮДЕНИЕ\4 Крыльцо офиса\ | K10: 4 Крыльцо офиса\K07156189_21_20260530T095532Z.jpg | L10: сб 30.05.2026 — 09:55:32 | M10: =HYPERLINK(склад2въезд13[[#This Row],[RelativePath]]) -> 4 Крыльцо офиса\K07156189_21_20260530T095532Z.jpg
A11: вс | B11: 46173 | C11: 0.65414352 | D11: без событий | E11: Территория | I11: K07156189_21_20260531T154158Z.jpg | J11: C:\ВИДЕОНАБЛЮДЕНИЕ\4 Крыльцо офиса\ | K11: 4 Крыльцо офиса\K07156189_21_20260531T154158Z.jpg | L11: вс 31.05.2026 — 15:41:58 | M11: =HYPERLINK(склад2въезд13[[#This Row],[RelativePath]]) -> 4 Крыльцо офиса\K07156189_21_20260531T154158Z.jpg
A12: вс | B12: 46173 | C12: 0.65505787 | D12: без событий | E12: Территория, сотрудники | I12: K07156189_21_20260531T154317Z.jpg | J12: C:\ВИДЕОНАБЛЮДЕНИЕ\4 Крыльцо офиса\ | K12: 4 Крыльцо офиса\K07156189_21_20260531T154317Z.jpg | L12: вс 31.05.2026 — 15:43:17 | M12: =HYPERLINK(склад2въезд13[[#This Row],[RelativePath]]) -> 4 Крыльцо офиса\K07156189_21_20260531T154317Z.jpg
A13: пн | B13: 46174 | C13: 0.5328588 | D13: Разгрузка | E13: Газель белая, фургон | F13: материалы | I13: K07156189_21_20260601T124719Z.jpg | J13: C:\ВИДЕОНАБЛЮДЕНИЕ\4 Крыльцо офиса\ | K13: 4 Крыльцо офиса\K07156189_21_20260601T124719Z.jpg | L13: пн 01.06.2026 — 12:47:19 | M13: =HYPERLINK(склад2въезд13[[#This Row],[RelativePath]]) -> 4 Крыльцо офиса\K07156189_21_20260601T124719Z.jpg
A14: пн | B14: 46174 | C14: 0.53758102 | D14: Разгрузка | E14: Газель белая, фургон | F14: материалы | H14: динамика | I14: K07156189_21_20260601T125407Z.jpg | J14: C:\ВИДЕОНАБЛЮДЕНИЕ\4 Крыльцо офиса\ | K14: 4 Крыльцо офиса\K07156189_21_20260601T125407Z.jpg | L14: пн 01.06.2026 — 12:54:07 | M14: =HYPERLINK(склад2въезд13[[#This Row],[RelativePath]]) -> 4 Крыльцо офиса\K07156189_21_20260601T125407Z.jpg
A15: пн | B15: 46174 | C15: 0.54799769 | D15: Стоянка | E15: Газель белая, фургон | I15: K07156189_21_20260601T130907Z.jpg | J15: C:\ВИДЕОНАБЛЮДЕНИЕ\4 Крыльцо офиса\ | K15: 4 Крыльцо офиса\K07156189_21_20260601T130907Z.jpg | L15: пн 01.06.2026 — 13:09:07 | M15: =HYPERLINK(склад2въезд13[[#This Row],[RelativePath]]) -> 4 Крыльцо офиса\K07156189_21_20260601T130907Z.jpg
A16: пн | B16: 46174 | C16: 0.85542824 | D16: Фиксация в кадре | E16: Территория | I16: K07156189_21_20260601T203149Z.jpg | J16: C:\ВИДЕОНАБЛЮДЕНИЕ\4 Крыльцо офиса\ | K16: 4 Крыльцо офиса\K07156189_21_20260601T203149Z.jpg | L16: пн 01.06.2026 — 20:31:49 | M16: =HYPERLINK(склад2въезд13[[#This Row],[RelativePath]]) -> 4 Крыльцо офиса\K07156189_21_20260601T203149Z.jpg
A17: вт | B17: 46175 | C17: 0.39883102 | D17: Фиксация в кадре | E17: Территория, сотрудники | I17: K07156189_21_20260602T093419Z.jpg | J17: C:\ВИДЕОНАБЛЮДЕНИЕ\4 Крыльцо офиса\ | K17: 4 Крыльцо офиса\K07156189_21_20260602T093419Z.jpg | L17: вт 02.06.2026 — 09:34:19 | M17: =HYPERLINK(склад2въезд13[[#This Row],[RelativePath]]) -> 4 Крыльцо офиса\K07156189_21_20260602T093419Z.jpg
A18: вт | B18: 46175 | C18: 0.42207176 | D18: Фиксация в кадре | E18: Территория | I18: K07156189_21_20260602T100747Z.jpg | J18: C:\ВИДЕОНАБЛЮДЕНИЕ\4 Крыльцо офиса\ | K18: 4 Крыльцо офиса\K07156189_21_20260602T100747Z.jpg | L18: вт 02.06.2026 — 10:07:47 | M18: =HYPERLINK(склад2въезд13[[#This Row],[RelativePath]]) -> 4 Крыльцо офиса\K07156189_21_20260602T100747Z.jpg
A19: вт | B19: 46175 | C19: 0.42943287 | D19: Загрузка | E19: Газель базы | F19: материалы | H19: площадка общага | I19: K07156189_21_20260602T101823Z.jpg | J19: C:\ВИДЕОНАБЛЮДЕНИЕ\4 Крыльцо офиса\ | K19: 4 Крыльцо офиса\K07156189_21_20260602T101823Z.jpg | L19: вт 02.06.2026 — 10:18:23 | M19: =HYPERLINK(склад2въезд13[[#This Row],[RelativePath]]) -> 4 Крыльцо офиса\K07156189_21_20260602T101823Z.jpg
A20: вт | B20: 46175 | C20: 0.43710648 | D20: Проезд | E20: Газель базы | F20: материалы | I20: K07156189_21_20260602T102926Z.jpg | J20: C:\ВИДЕОНАБЛЮДЕНИЕ\4 Крыльцо офиса\ | K20: 4 Крыльцо офиса\K07156189_21_20260602T102926Z.jpg | L20: вт 02.06.2026 — 10:29:26 | M20: =HYPERLINK(склад2въезд13[[#This Row],[RelativePath]]) -> 4 Крыльцо офиса\K07156189_21_20260602T102926Z.jpg
A21: вт | B21: 46175 | C21: 0.4446412 | D21: Фиксация в кадре | E21: Территория | I21: K07156189_21_20260602T104017Z.jpg | J21: C:\ВИДЕОНАБЛЮДЕНИЕ\4 Крыльцо офиса\ | K21: 4 Крыльцо офиса\K07156189_21_20260602T104017Z.jpg | L21: вт 02.06.2026 — 10:40:17 | M21: =HYPERLINK(склад2въезд13[[#This Row],[RelativePath]]) -> 4 Крыльцо офиса\K07156189_21_20260602T104017Z.jpg
A22: ср | B22: 46176 | C22: 0.46253472 | D22: Перемещение бревен | E22: Трактор базы | I22: K07156189_21_20260603T110603Z.jpg | J22: C:\ВИДЕОНАБЛЮДЕНИЕ\4 Крыльцо офиса\ | K22: 4 Крыльцо офиса\K07156189_21_20260603T110603Z.jpg | L22: ср 03.06.2026 — 11:06:03 | M22: =HYPERLINK(склад2въезд13[[#This Row],[RelativePath]]) -> 4 Крыльцо офиса\K07156189_21_20260603T110603Z.jpg
A23: чт | B23: 46177 | C23: 0.40076389 | D23: Фиксация в кадре | E23: Территория | I23: K07156189_21_20260604T093706Z.jpg | J23: C:\ВИДЕОНАБЛЮДЕНИЕ\4 Крыльцо офиса\ | K23: 4 Крыльцо офиса\K07156189_21_20260604T093706Z.jpg | L23: чт 04.06.2026 — 09:37:06 | M23: =HYPERLINK(склад2въезд13[[#This Row],[RelativePath]]) -> 4 Крыльцо офиса\K07156189_21_20260604T093706Z.jpg
A24: чт | B24: 46177 | C24: 0.53038194 | D24: Фиксация в кадре | E24: Территория | I24: K07156189_21_20260604T124345Z.jpg | J24: C:\ВИДЕОНАБЛЮДЕНИЕ\4 Крыльцо офиса\ | K24: 4 Крыльцо офиса\K07156189_21_20260604T124345Z.jpg | L24: чт 04.06.2026 — 12:43:45 | M24: =HYPERLINK(склад2въезд13[[#This Row],[RelativePath]]) -> 4 Крыльцо офиса\K07156189_21_20260604T124345Z.jpg
A25: чт | B25: 46177 | C25: 0.55540509 | D25: Фиксация в кадре | E25: Территория | I25: K07156189_21_20260604T131947Z.jpg | J25: C:\ВИДЕОНАБЛЮДЕНИЕ\4 Крыльцо офиса\ | K25: 4 Крыльцо офиса\K07156189_21_20260604T131947Z.jpg | L25: чт 04.06.2026 — 13:19:47 | M25: =HYPERLINK(склад2въезд13[[#This Row],[RelativePath]]) -> 4 Крыльцо офиса\K07156189_21_20260604T131947Z.jpg
A26: чт | B26: 46177 | C26: 0.67030093 | D26: Фиксация в кадре | E26: Территория | I26: K07156189_21_20260604T160514Z.jpg | J26: C:\ВИДЕОНАБЛЮДЕНИЕ\4 Крыльцо офиса\ | K26: 4 Крыльцо офиса\K07156189_21_20260604T160514Z.jpg | L26: чт 04.06.2026 — 16:05:14 | M26: =HYPERLINK(склад2въезд13[[#This Row],[RelativePath]]) -> 4 Крыльцо офиса\K07156189_21_20260604T160514Z.jpg
A27: чт | B27: 46177 | C27: 0.79219907 | D27: Фиксация в кадре | E27: Территория | I27: K07156189_21_20260604T190046Z.jpg | J27: C:\ВИДЕОНАБЛЮДЕНИЕ\4 Крыльцо офиса\ | K27: 4 Крыльцо офиса\K07156189_21_20260604T190046Z.jpg | L27: чт 04.06.2026 — 19:00:46 | M27: =HYPERLINK(склад2въезд13[[#This Row],[RelativePath]]) -> 4 Крыльцо офиса\K07156189_21_20260604T190046Z.jpg
A28: пт | B28: 46178 | C28: 0.52332176 | D28: Перемещение мешков с опилками | E28: Сотрудник | I28: K07156189_21_20260605T123335Z.jpg | J28: C:\ВИДЕОНАБЛЮДЕНИЕ\4 Крыльцо офиса\ | K28: 4 Крыльцо офиса\K07156189_21_20260605T123335Z.jpg | L28: пт 05.06.2026 — 12:33:35 | M28: =HYPERLINK(склад2въезд13[[#This Row],[RelativePath]]) -> 4 Крыльцо офиса\K07156189_21_20260605T123335Z.jpg
A29: пт | B29: 46178 | C29: 0.52346065 | D29: Загрузка | E29: chery tiggo, серый | F29: мешок с опилками | G29: 2 | I29: K07156189_21_20260605T123347Z.jpg | J29: C:\ВИДЕОНАБЛЮДЕНИЕ\4 Крыльцо офиса\ | K29: 4 Крыльцо офиса\K07156189_21_20260605T123347Z.jpg | L29: пт 05.06.2026 — 12:33:47 | M29: =HYPERLINK(склад2въезд13[[#This Row],[RelativePath]]) -> 4 Крыльцо офиса\K07156189_21_20260605T123347Z.jpg
A30: пт | B30: 46178 | C30: 0.5903588 | D30: Фиксация в кадре | E30: Территория | I30: K07156189_21_20260605T141007Z.jpg | J30: C:\ВИДЕОНАБЛЮДЕНИЕ\4 Крыльцо офиса\ | K30: 4 Крыльцо офиса\K07156189_21_20260605T141007Z.jpg | L30: пт 05.06.2026 — 14:10:07 | M30: =HYPERLINK(склад2въезд13[[#This Row],[RelativePath]]) -> 4 Крыльцо офиса\K07156189_21_20260605T141007Z.jpg
